<?xml version="1.0"?>
<robot xmlns:xacro="http://ros.org/wiki/xacro">

  <xacro:include filename="$(find four_wheel_drive_independent_steering)/urdf/common.xacro"/>

  <property name="steering_radius" value="0.100"/>
  <property name="steering_width" value="0.100"/>
  <property name="steering_mass" value="5.0"/>

  <xacro:macro name="steering" params="prefix parent *joint_origin *joint_axis">
    <joint name="${prefix}_steering_joint" type="revolute">
      <insert_block name="joint_origin"/>
      <parent link="${parent}"/>
      <child link="${prefix}_steering_link"/>
      <insert_block name="joint_axis"/>
      <limit effort="2.323" velocity="30" upper="${M_PI/1.5}" lower="${-M_PI/1.5}"/>
    </joint>

    <link name="${prefix}_steering_link">
      <visual>
        <geometry>
          <cylinder radius="${steering_radius}" length="${steering_width}"/>
        </geometry>
      </visual>
      <collision>
        <origin xyz="0 0 0" rpy="0 0 0"/>
        <geometry>
          <cylinder radius="${steering_radius}" length="${steering_width}"/>
        </geometry>
      </collision>
      <inertial>
        <origin xyz="0 0 0" rpy="0 0 0"/>
        <cylinder_inertial mass="${steering_mass}"
          radius="${steering_radius}" length="${steering_width}"/>
      </inertial>
    </link>
  </xacro:macro>

  <xacro:macro name="steering_gazebo" params="prefix">
    <gazebo reference="${prefix}_steering_link">
      <selfCollide>false</selfCollide>
      <mu1 value="0.8"/>
      <mu2 value="0.8"/>
    </gazebo>
  </xacro:macro>

  <xacro:macro name="steering_trans" params="prefix">
    <transmission name="${prefix}_steering_trans">
      <type>transmission_interface/SimpleTransmission</type>
      <joint name="${prefix}_steering_joint">
        <hardwareInterface>hardware_interface/VelocityJointInterface</hardwareInterface>
      </joint>
      <actuator name="${prefix}_steering_motor">
        <hardwareInterface>hardware_interface/velocityJointInterface</hardwareInterface>
        <mechanicalReduction>30</mechanicalReduction>
      </actuator>
    </transmission>
  </xacro:macro>

</robot>
