<?xml version="1.0"?>
<robot xmlns:xacro="http://ros.org/wiki/xacro">

  <xacro:include filename="$(find four_wheel_drive_independent_steering)/urdf/common.xacro"/>

  <property name="wheel_radius" value="0.075"/>
  <property name="wheel_width" value="0.030"/>
  <property name="wheel_mass" value="2.0"/>

  <xacro:macro name="wheel" params="prefix parent *joint_origin *joint_axis">
    <joint name="${prefix}_wheel_joint" type="continuous">
      <insert_block name="joint_origin"/>
      <parent link="${parent}"/>
      <child link="${prefix}_wheel_link"/>
      <insert_block name="joint_axis"/>
      <limit velocity="30" effort="2.323"/>
    </joint>

    <link name="${prefix}_wheel_link">
      <visual>
        <geometry>
          <cylinder radius="${wheel_radius}" length="${wheel_width}"/>
        </geometry>
      </visual>
      <collision>
        <origin xyz="0 0 0" rpy="0 0 0"/>
        <geometry>
          <cylinder radius="${wheel_radius}" length="${wheel_width}"/>
        </geometry>
      </collision>
      <inertial>
        <origin xyz="0 0 0" rpy="0 0 0"/>
        <cylinder_inertial mass="${wheel_mass}"
          radius="${wheel_radius}" length="${wheel_width}"/>
      </inertial>
    </link>
  </xacro:macro>

  <xacro:macro name="wheel_gazebo" params="prefix">
    <gazebo reference="${prefix}_wheel_link">
      <selfCollide>false</selfCollide>
      <mu1 value="0.8"/>
      <mu2 value="0.8"/>
    </gazebo>
  </xacro:macro>

  <xacro:macro name="wheel_trans" params="prefix">
    <transmission name="${prefix}_wheel_trans">
      <type>transmission_interface/SimpleTransmission</type>
      <joint name="${prefix}_wheel_joint">
        <hardwareInterface>hardware_interface/VelocityJointInterface</hardwareInterface>
      </joint>
      <actuator name="${prefix}_wheel_motor">
        <hardwareInterface>hardware_interface/VelocityJointInterface</hardwareInterface>
        <mechanicalReduction>30</mechanicalReduction>
      </actuator>
    </transmission>
  </xacro:macro>

</robot>
